Workbook

Sheet ITEMIZADO INTERNO
A1: ITEMIZADO INTERNO — USO EXCLUSIVO IAPATAGONIA SpA
A3: N° Oferta: | C3: 0602PVZ1PVN
A4: Cliente: | C4: Sr. Claudio Pavez
A5: Proyecto: | C5: Sistema Fotovoltaico Híbrido Residencial 4,84 kWp + Net Billing
A6: Localidad: | C6: Punucapa, Valdivia (Región de Los Ríos)
A7: Calculado por: | C7: Javier Bitterlich
A8: Fecha: | C8: 46175
A9: Plazo de ejecución: | C9: 10 días hábiles desde recepción de equipos
A11: Sección | B11: Ítem | C11: Descripción | D11: Und | E11: Cant. | F11: Costo Unit. | G11: Costo Total | H11: % Margen | I11: Margen $ | J11: P. Venta Unit. | K11: Total Venta
A12: 1 | C12: EQUIPOS FOTOVOLTAICOS PRINCIPALES
A13: 1 | B13: 1.1 | C13: Panel solar bifacial Trina Solar TSM-NEG19RC.20 605 Wp N-Type TopCon (certificado SEC) | D13: ud | E13: 8 | F13: 89340 | G13: =E13*F13 -> 714720 | H13: 0.25 | I13: =G13*H13 -> 178680 | J13: =F13*(1+H13) -> 111675 | K13: =G13+I13 -> 893400
A14: 1 | B14: 1.2 | C14: Inversor Híbrido Monofásico GoodWe GW3600-ES-20 3,6 kW · 2 MPPT (certificado SEC, Net Billing-ready) | D14: ud | E14: 1 | F14: 811024 | G14: =E14*F14 -> 811024 | H14: 0.25 | I14: =G14*H14 -> 202756 | J14: =F14*(1+H14) -> 1013780 | K14: =G14+I14 -> 1013780
A15: 2 | C15: ESTRUCTURA Y CABLEADO
A16: 2 | B16: 2.1 | C16: Estructura aluminio reforzada — pata delantera base ajustable + pata trasera 25°-40° ajustable, clamps medios y finales, anclaje PAT cobre, riel 5000 mm reforzado + coplas | D16: gl | E16: 1 | F16: 159366 | G16: =E16*F16 -> 159366 | H16: 0.25 | I16: =G16*H16 -> 39841.5 | J16: =F16*(1+H16) -> 199207.5 | K16: =G16+I16 -> 199207.5
A17: 2 | B17: 2.2 | C17: Cable solar DC H1Z2Z2-K 6 mm² · rollos 50 m negro/rojo (caída V < 1,5%) | D17: m | E17: 100 | F17: 948 | G17: =E17*F17 -> 94800 | H17: 0.25 | I17: =G17*H17 -> 23700 | J17: =F17*(1+H17) -> 1185 | K17: =G17+I17 -> 118500
A18: 2 | B18: 2.3 | C18: Cable AC RV-K 3×6 mm² inversor-tablero + canalización (caída V < 3%) | D18: gl | E18: 1 | F18: 151260 | G18: =E18*F18 -> 151260 | H18: 0.25 | I18: =G18*H18 -> 37815 | J18: =F18*(1+H18) -> 189075 | K18: =G18+I18 -> 189075
A19: 2 | B19: 2.4 | C19: Conectores MC4 macho/hembra, prensaestopas, sujeción y etiquetado normativo | D19: gl | E19: 1 | F19: 67228 | G19: =E19*F19 -> 67228 | H19: 0.25 | I19: =G19*H19 -> 16807 | J19: =F19*(1+H19) -> 84035 | K19: =G19+I19 -> 84035
A20: 2 | B20: 2.5 | C20: Base estructura montaje (Apoyos de Hormigón) | D20: ud | E20: 16 | F20: 13750 | G20: =E20*F20 -> 220000 | H20: 0.25 | I20: =G20*H20 -> 55000 | J20: =F20*(1+H20) -> 17187.5 | K20: =G20+I20 -> 275000
A21: 3 | C21: TABLEROS Y PROTECCIONES ELÉCTRICAS
A22: 3 | B22: 3.1 | C22: Gabinete DC IP65 con fusibles gPV 15A + DPS tipo II clase DC 20 kA | D22: ud | E22: 1 | F22: 151260 | G22: =E22*F22 -> 151260 | H22: 0.25 | I22: =G22*H22 -> 37815 | J22: =F22*(1+H22) -> 189075 | K22: =G22+I22 -> 189075
A23: 3 | B23: 3.2 | C23: Gabinete AC con interruptor termomagnético 25A curva C + diferencial 30 mA tipo A + DPS tipo II 40 kA + barra neutro | D23: ud | E23: 1 | F23: 184874 | G23: =E23*F23 -> 184874 | H23: 0.25 | I23: =G23*H23 -> 46218.5 | J23: =F23*(1+H23) -> 231092.5 | K23: =G23+I23 -> 231092.5
A24: 3 | B24: 3.3 | C24: Sistema puesta a tierra: jabalina Cu 2,4 m + cable Cu desnudo 35 mm² + conectores (R ≤ 25 Ω) | D24: gl | E24: 1 | F24: 126050 | G24: =E24*F24 -> 126050 | H24: 0.25 | I24: =G24*H24 -> 31512.5 | J24: =F24*(1+H24) -> 157562.5 | K24: =G24+I24 -> 157562.5
A25: 4 | C25: INGENIERÍA, INSTALACIÓN Y SERVICIOS
A26: 4 | B26: 4.1 | C26: Ingeniería: memoria de cálculo + diagrama unifilar + planos planta (con sello eléctrico SEC) | D26: gl | E26: 1 | F26: 294118 | G26: =E26*F26 -> 294118 | H26: 0.25 | I26: =G26*H26 -> 73529.5 | J26: =F26*(1+H26) -> 367647.5 | K26: =G26+I26 -> 367647.5
A27: 4 | B27: 4.2 | C27: Tramitación SEC: declaración TE4 + gestión Saesa + inscripción Net Billing (Ley 21.118) | D27: gl | E27: 1 | F27: 235294 | G27: =E27*F27 -> 235294 | H27: 0.25 | I27: =G27*H27 -> 58823.5 | J27: =F27*(1+H27) -> 294117.5 | K27: =G27+I27 -> 294117.5
A28: 4 | B28: 4.3 | C28: Mano de obra: instalación electromecánica completa (estructura, módulos, cableado DC/AC, tableros) | D28: kW | E28: 3.6 | F28: 193278 | G28: =E28*F28 -> 695800.8 | H28: 0.25 | I28: =G28*H28 -> 173950.2 | J28: =F28*(1+H28) -> 241597.5 | K28: =G28+I28 -> 869751
A29: 4 | B29: 4.4 | C29: Puesta en servicio: comisionamiento, pruebas funcionales, configuración monitoreo SEMS GoodWe | D29: gl | E29: 1 | F29: 168068 | G29: =E29*F29 -> 168068 | H29: 0.25 | I29: =G29*H29 -> 42017 | J29: =F29*(1+H29) -> 210085 | K29: =G29+I29 -> 210085
A30: 4 | B30: 4.5 | C30: Flete: Puerto Montt → Valdivia (equipos + materiales) | D30: gl | E30: 1 | F30: 235294 | G30: =E30*F30 -> 235294 | H30: 0.25 | I30: =G30*H30 -> 58823.5 | J30: =F30*(1+H30) -> 294117.5 | K30: =G30+I30 -> 294117.5
I35: TOTAL COSTOS: | K35: =SUMIF(B12:B33,"<>",G12:G33) -> 4309156.8
I36: TOTAL MARGEN: | K36: =SUMIF(B12:B33,"<>",I12:I33) -> 1077289.2
I37: TOTAL NETO VENTA: | K37: =SUMIF(B13:B30,"<>",K13:K30) -> 5386446
I38: IVA (19%): | K38: =K37*0.19 -> 1023424.7
I39: TOTAL CON IVA: | K39: =K37+K38 -> 6409870.7
I40: % Margen efectivo: | K40: =IFERROR(K36/K35,0) -> 0.25
I41: * Valor sujeto a evaluacion de visita Técnica
A43: Leyenda: texto azul = celdas editables (Cantidad, Costo Unit., %Margen). Texto negro = fórmulas calculadas. Los cambios aquí se reflejan automáticamente en la hoja COTIZACION CLIENTE.

Sheet COTIZACION CLIENTE
C1: IAPATAGONIA SpA
C2: RUT 77.406.457-5 · C. Pedro Lagos MZ1 C12, René Schneider, Puerto Montt Cta. cte. Banco Santander N° 93390253 · contacto@iapatagonia.cl
A4: COTIZACIÓN
A6: N° Oferta: | B6: 0602PVZ1PVN | C6: Fecha: | D6: =TODAY() -> 46177
A7: Cliente: | B7: Claudio Pavez | C7: Localidad: | D7: Punucapa, Valdivia (Región de Los Ríos)
A8: Atención: | B8: Sr. Claudio Pavez
A9: Proyecto: | B9: Sistema Fotovoltaico Híbrido Residencial 4,84 kWp + Net Billing
A11: Ítem | B11: Descripción | C11: Und | D11: Cant. | E11: P. Unitario | F11: Total
A12: 1 | B12: EQUIPOS FOTOVOLTAICOS PRINCIPALES
A13: ='ITEMIZADO INTERNO'!B13 -> 1.1 | B13: ='ITEMIZADO INTERNO'!C13 -> Panel solar bifacial Trina Solar TSM-NEG19RC.20 605 Wp N-Type TopCon (certificado SEC) | C13: ='ITEMIZADO INTERNO'!D13 -> ud | D13: ='ITEMIZADO INTERNO'!E13 -> 8 | E13: ='ITEMIZADO INTERNO'!J13 -> 111675 | F13: ='ITEMIZADO INTERNO'!K13 -> 893400
A14: ='ITEMIZADO INTERNO'!B14 -> 1.2 | B14: ='ITEMIZADO INTERNO'!C14 -> Inversor Híbrido Monofásico GoodWe GW3600-ES-20 3,6 kW · 2 MPPT (certificado SEC, Net Billing-ready) | C14: ='ITEMIZADO INTERNO'!D14 -> ud | D14: ='ITEMIZADO INTERNO'!E14 -> 1 | E14: ='ITEMIZADO INTERNO'!J14 -> 1013780 | F14: ='ITEMIZADO INTERNO'!K14 -> 1013780
A15: 2 | B15: ESTRUCTURA Y CABLEADO
A16: ='ITEMIZADO INTERNO'!B16 -> 2.1 | B16: ='ITEMIZADO INTERNO'!C16 -> Estructura aluminio reforzada — pata delantera base ajustable + pata trasera 25°-40° ajustable, clamps medios y finales, anclaje PAT cobre, riel 5000 mm reforzado + coplas | C16: ='ITEMIZADO INTERNO'!D16 -> gl | D16: ='ITEMIZADO INTERNO'!E16 -> 1 | E16: ='ITEMIZADO INTERNO'!J16 -> 199207.5 | F16: ='ITEMIZADO INTERNO'!K16 -> 199207.5
A17: ='ITEMIZADO INTERNO'!B17 -> 2.2 | B17: ='ITEMIZADO INTERNO'!C17 -> Cable solar DC H1Z2Z2-K 6 mm² · rollos 50 m negro/rojo (caída V < 1,5%) | C17: ='ITEMIZADO INTERNO'!D17 -> m | D17: ='ITEMIZADO INTERNO'!E17 -> 100 | E17: ='ITEMIZADO INTERNO'!J17 -> 1185 | F17: ='ITEMIZADO INTERNO'!K17 -> 118500
A18: ='ITEMIZADO INTERNO'!B18 -> 2.3 | B18: ='ITEMIZADO INTERNO'!C18 -> Cable AC RV-K 3×6 mm² inversor-tablero + canalización (caída V < 3%) | C18: ='ITEMIZADO INTERNO'!D18 -> gl | D18: ='ITEMIZADO INTERNO'!E18 -> 1 | E18: ='ITEMIZADO INTERNO'!J18 -> 189075 | F18: ='ITEMIZADO INTERNO'!K18 -> 189075
A19: ='ITEMIZADO INTERNO'!B19 -> 2.4 | B19: ='ITEMIZADO INTERNO'!C19 -> Conectores MC4 macho/hembra, prensaestopas, sujeción y etiquetado normativo | C19: ='ITEMIZADO INTERNO'!D19 -> gl | D19: ='ITEMIZADO INTERNO'!E19 -> 1 | E19: ='ITEMIZADO INTERNO'!J19 -> 84035 | F19: ='ITEMIZADO INTERNO'!K19 -> 84035
A20: 2.5 | B20: ='ITEMIZADO INTERNO'!C20 -> Base estructura montaje (Apoyos de Hormigón) | C20: ='ITEMIZADO INTERNO'!D20 -> ud | D20: ='ITEMIZADO INTERNO'!E20 -> 16 | E20: ='ITEMIZADO INTERNO'!J20 -> 17187.5 | F20: ='ITEMIZADO INTERNO'!K20 -> 275000
A21: 3 | B21: TABLEROS Y PROTECCIONES ELÉCTRICAS
A22: ='ITEMIZADO INTERNO'!B22 -> 3.1 | B22: ='ITEMIZADO INTERNO'!C22 -> Gabinete DC IP65 con fusibles gPV 15A + DPS tipo II clase DC 20 kA | C22: ='ITEMIZADO INTERNO'!D22 -> ud | D22: ='ITEMIZADO INTERNO'!E22 -> 1 | E22: ='ITEMIZADO INTERNO'!J22 -> 189075 | F22: ='ITEMIZADO INTERNO'!K22 -> 189075
A23: ='ITEMIZADO INTERNO'!B23 -> 3.2 | B23: ='ITEMIZADO INTERNO'!C23 -> Gabinete AC con interruptor termomagnético 25A curva C + diferencial 30 mA tipo A + DPS tipo II 40 kA + barra neutro | C23: ='ITEMIZADO INTERNO'!D23 -> ud | D23: ='ITEMIZADO INTERNO'!E23 -> 1 | E23: ='ITEMIZADO INTERNO'!J23 -> 231092.5 | F23: ='ITEMIZADO INTERNO'!K23 -> 231092.5
A24: ='ITEMIZADO INTERNO'!B24 -> 3.3 | B24: ='ITEMIZADO INTERNO'!C24 -> Sistema puesta a tierra: jabalina Cu 2,4 m + cable Cu desnudo 35 mm² + conectores (R ≤ 25 Ω) | C24: ='ITEMIZADO INTERNO'!D24 -> gl | D24: ='ITEMIZADO INTERNO'!E24 -> 1 | E24: ='ITEMIZADO INTERNO'!J24 -> 157562.5 | F24: ='ITEMIZADO INTERNO'!K24 -> 157562.5
A25: 4 | B25: INGENIERÍA, INSTALACIÓN Y SERVICIOS
A26: ='ITEMIZADO INTERNO'!B26 -> 4.1 | B26: ='ITEMIZADO INTERNO'!C26 -> Ingeniería: memoria de cálculo + diagrama unifilar + planos planta (con sello eléctrico SEC) | C26: ='ITEMIZADO INTERNO'!D26 -> gl | D26: ='ITEMIZADO INTERNO'!E26 -> 1 | E26: ='ITEMIZADO INTERNO'!J26 -> 367647.5 | F26: ='ITEMIZADO INTERNO'!K26 -> 367647.5
A27: ='ITEMIZADO INTERNO'!B27 -> 4.2 | B27: ='ITEMIZADO INTERNO'!C27 -> Tramitación SEC: declaración TE4 + gestión Saesa + inscripción Net Billing (Ley 21.118) | C27: ='ITEMIZADO INTERNO'!D27 -> gl | D27: ='ITEMIZADO INTERNO'!E27 -> 1 | E27: ='ITEMIZADO INTERNO'!J27 -> 294117.5 | F27: ='ITEMIZADO INTERNO'!K27 -> 294117.5
A28: ='ITEMIZADO INTERNO'!B28 -> 4.3 | B28: ='ITEMIZADO INTERNO'!C28 -> Mano de obra: instalación electromecánica completa (estructura, módulos, cableado DC/AC, tableros) | C28: ='ITEMIZADO INTERNO'!D28 -> kW | D28: ='ITEMIZADO INTERNO'!E28 -> 3.6 | E28: ='ITEMIZADO INTERNO'!J28 -> 241597.5 | F28: ='ITEMIZADO INTERNO'!K28 -> 869751
A29: ='ITEMIZADO INTERNO'!B29 -> 4.4 | B29: ='ITEMIZADO INTERNO'!C29 -> Puesta en servicio: comisionamiento, pruebas funcionales, configuración monitoreo SEMS GoodWe | C29: ='ITEMIZADO INTERNO'!D29 -> gl | D29: ='ITEMIZADO INTERNO'!E29 -> 1 | E29: ='ITEMIZADO INTERNO'!J29 -> 210085 | F29: ='ITEMIZADO INTERNO'!K29 -> 210085
A30: ='ITEMIZADO INTERNO'!B30 -> 4.5 | B30: ='ITEMIZADO INTERNO'!C30 -> Flete: Puerto Montt → Valdivia (equipos + materiales) | C30: ='ITEMIZADO INTERNO'!D30 -> gl | D30: ='ITEMIZADO INTERNO'!E30 -> 1 | E30: ='ITEMIZADO INTERNO'!J30 -> 294117.5 | F30: ='ITEMIZADO INTERNO'!K30 -> 294117.5
B35: * Valor sujeto a evaluacion de visita Técnica | E35: Total Neto: | F35: =SUMIF(D12:D33,">0",F12:F33) -> 5386446
E36: IVA (19%): | F36: =F35*0.19 -> 1023424.7
E37: TOTAL CON IVA: | F37: =F35+F36 -> 6409870.7
A39: ALCANCE DEL PROYECTO
A40: Suministro, instalación y puesta en servicio de sistema fotovoltaico híbrido residencial de 4,84 kWp nominales en Punucapa, Valdivia. Incluye: 8 paneles bifaciales Trina 605 Wp (montaje sobre estructura aluminio reforzada montada a piso sobre apoyos de hormigón con inclinación ajustable 25°-40°), inversor híbrido GoodWe 3,6 kW Net Billing-ready con 2 MPPT, tableros DC/AC con protecciones SEC (fusibles gPV, DPS clase II, IT 25A, ID 30 mA), puesta a tierra Cu (R≤25Ω), cableado solar 6 mm² y AC RV-K 3×6 mm². Servicios incluidos: ingeniería con sello eléctrico (memoria de cálculo + unifilar + planos), tramitación completa SEC (declaración TE4 e inscripción Net Billing ante Saesa, Ley 21.118), instalación electromecánica, comisionamiento, configuración monitoreo SEMS GoodWe y flete Puerto Montt-Valdivia. Generación anual esperada: 5.393 kWh (Performance Ratio 0,78; HSP Valdivia 4,16 kWh/m²/día). NO incluye 2 u batería de respaldo Pylontech US5000 suministradas por cliente.
A42: CONDICIONES COMERCIALES
A43: Plazo de ejecución: | C43: 10 días hábiles desde recepción de los equipos
A44: Validez de la oferta: | C44: 30 días corridos
A45: Forma de pago: | C45: 50% anticipo , 30% contra recepción de equipos en sitio, 20% contra puesta en servicio
A47: EMISIÓN DE ORDEN DE COMPRA A:
A48: IAPATAGONIA SpA
A49: RUT 77.406.457-5
A50: C. Pedro Lagos MZ1 C12, René Schneider, Puerto Montt
...
