Workbook

Sheet Resumen Valores kits y cotizado
A2: Kits GoodWe
A3: GOODWE | B3: Potencia | C3: Total iva incl. | E3: Columna 1 | F3: Descripcion | G3: Marca | H3: Modelo | I3: Valor | J3: cantidad | K3: Total
A4: ON GRID | B4: 3kW | C4: ='tablas de Precios kit BBDD Prod'!M51 -> 1585068.7 | E4: Inversor | F4: SUN2000 -4KTL-L1 | G4: =VLOOKUP($F4,Tabla_1[#ALL],2,) -> Huawei | H4: =VLOOKUP($F4,Tabla_1[#ALL],3,) -> INVERSOR HUAWEI ON GRID HIBRIDO MONOFASICO | I4: =VLOOKUP($F4,Tabla_1[#ALL],6,) -> 657500 | J4: 1 | K4: =I4*J4 -> 657500
B5: 4.2kW | C5: ='tablas de Precios kit BBDD Prod'!R51 -> 1644487.7 | E5: Panel | F5: Panel Bifacial Trina Solar 715Wp | G5: =VLOOKUP($F5,Tabla_1[#ALL],2,) -> Trina Solar | H5: =VLOOKUP($F5,Tabla_1[#ALL],3,) -> TSM NEG21C.20 715Wp | I5: =VLOOKUP($F5,Tabla_1[#ALL],6,) -> 132113.69 | J5: 9 | K5: =I5*J5 -> 1189023.2
B6: 5kW | C6: ='tablas de Precios kit BBDD Prod'!W51 -> 2198052.8 | E6: Bateria | F6: LUNA2000-5-E0 5KWH | G6: =VLOOKUP($F6,Tabla_1[#ALL],2,) -> Huawei | H6: =VLOOKUP($F6,Tabla_1[#ALL],3,) -> HUAWEI BATERIA DE LITIO LUNA2OOO 5KWH | I6: =VLOOKUP($F6,Tabla_1[#ALL],6,) -> 2070221.2 | J6: 1 | K6: =I6*J6 -> 2070221.2
B7: 6kW | C7: ='tablas de Precios kit BBDD Prod'!AB51 -> 2413658.7 | E7: Accesorios | F7: LUNA2000-5KW-CO | G7: =VLOOKUP($F7,Tabla_1[#ALL],2,) -> Huawei | H7: =VLOOKUP($F7,Tabla_1[#ALL],3,) -> MODULO DE POTENCIA PARA BATERIA DE LITIO | I7: =VLOOKUP($F7,Tabla_1[#ALL],6,) -> 781250 | J7: 1 | K7: =I7*J7 -> 781250
B8: 8.5kW | C8: ='tablas de Precios kit BBDD Prod'!AG51 -> 3346900.3 | E8: Accesorios | F8: BACKUP BOX-B0 | G8: =VLOOKUP($F8,Tabla_1[#ALL],2,) -> Huawei | H8: =VLOOKUP($F8,Tabla_1[#ALL],3,) -> HUAWEI BACKUP BOX-B0 MONOFASICO | I8: =VLOOKUP($F8,Tabla_1[#ALL],6,) -> 596092.5 | J8: 1 | K8: =I8*J8 -> 596092.5
B9: 10kW | C9: ='tablas de Precios kit BBDD Prod'!AL51 -> 4094375.2 | E9: Accesorios | F9: SDongleA-05 | G9: =VLOOKUP($F9,Tabla_1[#ALL],2,) -> Huawei | H9: =VLOOKUP($F9,Tabla_1[#ALL],3,) -> HUAWEI SMART DONGLE WLAN FE | I9: =VLOOKUP($F9,Tabla_1[#ALL],6,) -> 78805 | J9: 1 | K9: =I9*J9 -> 78805
E10: Accesorios | F10: DDSU666-H | G10: =VLOOKUP($F10,Tabla_1[#ALL],2,) -> Huawei | H10: =VLOOKUP($F10,Tabla_1[#ALL],3,) -> HUAWEI SMART POWER SENSOR DDSU666-H | I10: =VLOOKUP($F10,Tabla_1[#ALL],6,) -> 70606.25 | J10: 1 | K10: =I10*J10 -> 70606.25
A11: HIBRIDOS | B11: 3kW | C11: ='tablas de Precios kit BBDD Prod'!M26 -> 3190395.9 | J11: 1 | K11: =I11*J11 -> 0
B12: 3.6kW | C12: ='tablas de Precios kit BBDD Prod'!R26 -> 3213182.5 | J12: 1 | K12: =I12*J12 -> 0
B13: 5kW | C13: ='tablas de Precios kit BBDD Prod'!W26 -> 3863354.8 | J13: 1 | K13: =I13*J13 -> 0
B14: 6kW | C14: ='tablas de Precios kit BBDD Prod'!AB26 -> 3962824.6 | J14: 1 | K14: =I14*J14 -> 0
B15: 8kW | C15: ='tablas de Precios kit BBDD Prod'!AG26 -> 5776631 | J15: 1 | K15: =I15*J15 -> 0
B16: 10kW | C16: ='tablas de Precios kit BBDD Prod'!AL26 -> 6523115.2 | J16: 1 | K16: =I16*J16 -> 0
B17: 12kW | C17: ='tablas de Precios kit BBDD Prod'!AQ26 -> 6692813.8 | J17: 1 | K17: =I17*J17 -> 0
J18: 1 | K18: =I18*J18 -> 0
J19: 1 | K19: =I19*J19 -> 0
A20: Kits HUAWEI | J20: 1 | K20: =I20*J20 -> 0
A21: HUAWEI | B21: Potencia | C21: Total iva incl. | J21: 1 | K21: =I21*J21 -> 0
A22: HIBRIDOS | B22: 2kW | C22: ='tablas de Precios kit BBDD Prod'!M80 -> 6101754.8 | J22: 1 | K22: =I22*J22 -> 0
B23: 4kW | C23: ='tablas de Precios kit BBDD Prod'!R80 -> 6017663.1 | J23: 1 | K23: =I23*J23 -> 0
B24: 6kW | C24: ='tablas de Precios kit BBDD Prod'!W80 -> 6978062.2 | J24: 1 | K24: =I24*J24 -> 0
K25: =I25*J25 -> 0
A26: ON-GRID | B26: 2kW | C26: ='tablas de Precios kit BBDD Prod'!M103 -> 1832971.4 | K26: =I26*J26 -> 0
B27: 4kW | C27: ='tablas de Precios kit BBDD Prod'!R103 -> 2053269.7 | K27: =SUM(K4:K26) -> 5443498.2
B28: 6kW | C28: ='tablas de Precios kit BBDD Prod'!W103 -> 3006468.8 | J28: IVA | K28: =K27*0.19 -> 1034264.7
J29: Total | K29: =SUM(K27:K28) -> 6477762.9
A31: Componentes del kit
A32: Modulos FV
A33: Inversor
A34: Bateria
A35: Riel 5m
A36: Fijación Tipo L Madera
A37: Copla Riel Reforzado
A38: Clams medio
A39: Clams final
A40: MC4 macho
A41: MC4 hembra
A42: Cable solar rojo 6mm
...

Sheet BBDD conjunta
C2: Descripcion | D2: Marca | E2: Modelo | F2: Valor | G2: Margen | H2: total
C3: Panel solar bifacial Trina Solar 610Wp | D3: Trina Solar | E3: TSM NEG19RC.20 610Wp | F3: 89820 | G3: 1.25 | H3: =F3*G3 -> 112275
C4: Panel solar bifacial Trina Solar 605Wp | D4: Trina Solar | E4: TSM NEG19RC.20 605Wp | F4: 89340 | G4: 1.25 | H4: =F4*G4 -> 111675
C5: Panel solar bifacial Trina Solar 705Wp | D5: Trina Solar | E5: TSM NEG21C.20 705Wp | F5: 104358 | G5: 1.25 | H5: =F5*G5 -> 130447.5
C6: Panel solar bifacial Trina Solar 700Wp | D6: Trina Solar | E6: TSM NEG21C.20 700Wp | F6: 105104 | G6: 1.25 | H6: =F6*G6 -> 131380
C7: Panel Bifacial Trina Solar 715Wp | D7: Trina Solar | E7: TSM NEG21C.20 715Wp | F7: 105690.95 | G7: 1.25 | H7: =F7*G7 -> 132113.69
C8: Panel Solar Bifacial JA Solar 615Wp | D8: JA Solar | E8: JAM66D45LB 615Wp | F8: 90909 | G8: 1.25 | H8: =F8*G8 -> 113636.25
C9: Panel Solar Bifacial JA Solar 715Wp | D9: JA Solar | E9: JAM66D45LB 715Wp | F9: 105690.95 | G9: 1.25 | H9: =F9*G9 -> 132113.69
C10: Conector MC4 macho original Trina Solar | D10: Trina Solar | E10: MC4 Trina Solar Macho | F10: 680 | G10: 1.25 | H10: =F10*G10 -> 850
C11: Conector MC4 hembra original Trina Solar | D11: Trina Solar | E11: MC4 Trina Solar Hembra | F11: 680 | G11: 1.25 | H11: =F11*G11 -> 850
C12: GoodWe licencia activación SERIE ES- 20 | D12: GoodWe | E12: Activation Code to: GW....-ES-20 [Híbrido FLEX] | F12: 156800 | G12: 1.25 | H12: =F12*G12 -> 196000
C13: GoodWe licencia activación SERIE ET-20 | D13: GoodWe | E13: Activation Code to: GW....-ET-20 [Híbrido FLEX] | F13: 213458.82 | G13: 1.25 | H13: =F13*G13 -> 266823.53
C14: GoodWe licencia activación SERIE ET | D14: GoodWe | E14: Activation Code to: GW....-ET[Híbrido FLEX] | F14: 322823.53 | G14: 1.25 | H14: =F14*G14 -> 403529.41
... C83: Módulo de comunicación 4G para monitoreo remoto GoodWe | D83: GoodWe | E83: 4G Module | F83: 81200 | G83: 1.25 | H83: =F83*G83 -> 101500

Sheet tablas de Precios kit BBDD Prod
B1: Categoría | C1: SAP | D1: Marca | E1: Modelo | F1: Descripcion | G1: Precio (neto)
B2: Paneles Solares | C2: 106562 | D2: Trina Solar | E2: TSM NEG19RC.20 610Wp | F2: Panel solar bifacial Trina Solar 610Wp | G2: 89820
C3: 107405 | D3: Trina Solar | E3: TSM NEG19RC.20 605Wp | F3: Panel solar bifacial Trina Solar 605Wp | G3: 89340
C4: 106597 | D4: Trina Solar | E4: TSM NEG21C.20 705Wp | F4: Panel solar bifacial Trina Solar 705Wp | G4: 104358
C5: 107404 | D5: Trina Solar | E5: TSM NEG21C.20 700Wp | F5: Panel solar bifacial Trina Solar 700Wp | G5: 105104
C6: 108404 | D6: Trina Solar | E6: TSM NEG21C.20 715Wp | F6: Panel Bifacial Trina Solar 715Wp | G6: 105690.95 | I6: GOODWE Kit 3kW hibrido 5kWh | N6: GOODWE Kit 3.6kW hibrido 5kWh | S6: GOODWE Kit 5kW hibrido 5kWh | X6: GOODWE Kit 6kW hibrido 5kWh | AC6: GOODWE Kit 8.5kW hibrido 10kWh | AH6: GOODWE Kit 10kW hibrido 10kWh | AM6: GOODWE Kit 12kW hibrido 10kWh
C7: 108407 | D7: JA Solar | E7: JAM66D45LB 615Wp | F7: Panel Solar Bifacial JA Solar 615Wp | G7: 90909
C8: 108408 | D8: JA Solar | E8: JAM66D45LB 715Wp | F8: Panel Solar Bifacial JA Solar 715Wp | G8: 105690.95
B9: Conector MC4 | C9: 106641 | D9: Trina Solar | E9: MC4 Trina Solar Macho | F9: Conector MC4 macho original Trina Solar | G9: 680
C10: 106642 | D10: Trina Solar | E10: MC4 Trina Solar Hembra | F10: Conector MC4 hembra original Trina Solar | G10: 680 | L10: unidad | M10: total | Q10: unidad | R10: total | V10: unidad | W10: total | AA10: unidad | AB10: total | AF10: unidad | AG10: total | AK10: unidad | AL10: total | AP10: unidad | AQ10: total
B11: Inversores | C11: 106998 | D11: GoodWe | E11: Activation Code to: GW....-ES-20 [Híbrido FLEX] | F11: GoodWe licencia activación SERIE ES- 20 | G11: 156800 | I11: TSM NEG21C.20 715Wp | J11: Trina Solar 715Wp | K11: =$G$6 -> 105690.95 | L11: 6 | M11: =K11*L11 -> 634145.71 | N11: TSM NEG21C.20 715Wp | O11: Trina Solar 715Wp | P11: =$G$6 -> 105690.95 | Q11: 6 | R11: =P11*Q11 -> 634145.71 | S11: TSM NEG21C.20 715Wp | T11: Trina Solar 715Wp | U11: =$G$6 -> 105690.95 | V11: 9 | W11: =U11*V11 -> 951218.56 | X11: TSM NEG21C.20 715Wp | Y11: modulos 715W | Z11: =$G$6 -> 105690.95 | AA11: 9 | AB11: =Z11*AA11 -> 951218.56 | AC11: TSM NEG21C.20 715Wp | AD11: Trina Solar 715Wp | AE11: =$G$6 -> 105690.95 | AF11: 14 | AG11: =AE11*AF11 -> 1479673.3 | AH11: TSM NEG21C.20 715Wp | AI11: Trina Solar 715Wp | AJ11: =$G$6 -> 105690.95 | AK11: 18 | AL11: =AJ11*AK11 -> 1902437.1 | AM11: TSM NEG21C.20 715Wp | AN11: Trina Solar 715Wp | AO11: =$G$6 -> 105690.95 | AP11: 18 | AQ11: =AO11*AP11 -> 1902437.1
C12: 106993 | D12: GoodWe | E12: Activation Code to: GW....-ET-20 [Híbrido FLEX] | F12: GoodWe licencia activación SERIE ET-20 | G12: 213458.82 | I12: GW3000-ES-20 | J12: Inversor 3kW hibrido | K12: =$G$29 -> 795200 | L12: 1 | M12: =K12*L12 -> 795200 | N12: GW3600-ES-20 | O12: Inversor 3.6kW hibrido | P12: 811024 | Q12: 1 | R12: =P12*Q12 -> 811024 | S12: GW5000-ES-20 | T12: Inversor 5kW hibrido | U12: =$G$31 -> 897259.7 | V12: 1 | W12: =U12*V12 -> 897259.7 | X12: GW6000-ES-20 | Y12: Inversor 6kW hibrido | Z12: 966336 | AA12: 1 | AB12: =Z12*AA12 -> 966336 | AC12: GW8000-ES-C10 | AD12: Inversor 8.5kW hibrido | AE12: 1005813 | AF12: 1 | AG12: =AE12*AF12 -> 1005813 | AH12: GW10K-ES-C10 | AI12: Inversor 10kW hibrido | AJ12: 1043625 | AK12: 1 | AL12: =AJ12*AK12 -> 1043625 | AM12: GW12K-ES-C10 | AN12: Inversor 12kW hibrido | AO12: 1156031.2 | AP12: 1 | AQ12: =AO12*AP12 -> 1156031.2
C13: 106992 | D13: GoodWe | E13: Activation Code to: GW....-ET[Híbrido FLEX] | F13: GoodWe licencia activación SERIE ET | G13: 322823.53 | I13: LX A5.0-30 w/ Wall-Mounted Accessory Pack | J13: Bateria 5kWh | K13: =$G$51 -> 640000 | L13: 1 | M13: =K13*L13 -> 640000 | N13: LX A5.0-30 w/ Wall-Mounted Accessory Pack | O13: Bateria 5kWh | P13: =$G$51 -> 640000 | Q13: 1 | R13: =P13*Q13 -> 640000 | S13: LX A5.0-30 w/ Wall-Mounted Accessory Pack | T13: Bateria 5kWh | U13: =$G$51 -> 640000 | V13: 1 | W13: =U13*V13 -> 640000 | X13: LX A5.0-30 w/ Wall-Mounted Accessory Pack | Y13: Bateria 5kWh | Z13: =$G$51 -> 640000 | AA13: 1 | AB13: =Z13*AA13 -> 640000 | AC13: LX A5.0-30 w/ Wall-Mounted Accessory Pack | AD13: Bateria 5kWh | AE13: =$G$51 -> 640000 | AF13: 2 | AG13: =AE13*AF13 -> 1280000 | AH13: LX A5.0-30 w/ Wall-Mounted Accessory Pack | AI13: Bateria 5kWh | AJ13: =$G$51 -> 640000 | AK13: 2 | AL13: =AJ13*AK13 -> 1280000 | AM13: LX A5.0-30 w/ Wall-Mounted Accessory Pack | AN13: Bateria 5kWh | AO13: =$G$51 -> 640000 | AP13: 2 | AQ13: =AO13*AP13 -> 1280000
C14: 106942 | D14: GoodWe | E14: STS200-80-10 | F14: GoodWe Equipo Transferencia Estatica 200A | G14: 914270.56 | J14: Riel 5m | K14: =$G$82 -> 18320 | L14: 3 | M14: =K14*L14 -> 54960 | O14: Riel 5m | P14: =$G$82 -> 18320 | Q14: 3 | R14: =P14*Q14 -> 54960 | T14: Riel 5m | U14: =$G$82 -> 18320 | V14: 5 | W14: =U14*V14 -> 91600 | Y14: Riel 5m | Z14: =$G$82 -> 18320 | AA14: 5 | AB14: =Z14*AA14 -> 91600 | AD14: Riel 5m | AE14: =$G$82 -> 18320 | AF14: 7 | AG14: =AE14*AF14 -> 128240 | AI14: Riel 5m | AJ14: =$G$82 -> 18320 | AK14: 9 | AL14: =AJ14*AK14 -> 164880 | AN14: Riel 5m | AO14: =$G$82 -> 18320 | AP14: 9 | AQ14: =AO14*AP14 -> 164880
C15: 108053 | D15: GoodWe | E15: GW125K-STS-G10 | F15: GoodWe Equipo Transferencia Estatica 125kW | G15: 1784000 | J15: Fijación Tipo L Madera | K15: =$G$69 -> 1100 | L15: 10 | M15: =K15*L15 -> 11000 | O15: Fijación Tipo L Madera | P15: =$G$69 -> 1100 | Q15: 10 | R15: =P15*Q15 -> 11000 | T15: Fijación Tipo L Madera | U15: =$G$69 -> 1100 | V15: 16 | W15: =U15*V15 -> 17600 | Y15: Fijación Tipo L Madera | Z15: =$G$69 -> 1100 | AA15: 16 | AB15: =Z15*AA15 -> 17600 | AD15: Fijación Tipo L Madera | AE15: =$G$69 -> 1100 | AF15: 22 | AG15: =AE15*AF15 -> 24200 | AI15: Fijación Tipo L Madera | AJ15: =$G$69 -> 1100 | AK15: 34 | AL15: =AJ15*AK15 -> 37400 | AN15: Fijación Tipo L Madera | AO15: =$G$69 -> 1100 | AP15: 34 | AQ15: =AO15*AP15 -> 37400
C16: 106694 | D16: GoodWe | E16: GW3000-DNS-30 | F16: Inversor On Grid Monofásico GoodWe 3kW – 2 MPPT | G16: 325389.47 | J16: Copla Riel Reforzado | K16: =$G$85 -> 2500 | L16: 4 | M16: =K16*L16 -> 10000 | O16: Copla Riel Reforzado | P16: =$G$85 -> 2500 | Q16: 4 | R16: =P16*Q16 -> 10000 | T16: Copla Riel Reforzado | U16: =$G$85 -> 2500 | V16: 4 | W16: =U16*V16 -> 10000 | Y16: Copla Riel Reforzado | Z16: =$G$85 -> 2500 | AA16: 4 | AB16: =Z16*AA16 -> 10000 | AD16: Copla Riel Reforzado | AE16: =$G$85 -> 2500 | AF16: 4 | AG16: =AE16*AF16 -> 10000 | AI16: Copla Riel Reforzado | AJ16: =$G$85 -> 2500 | AK16: 6 | AL16: =AJ16*AK16 -> 15000 | AN16: Copla Riel Reforzado | AO16: =$G$85 -> 2500 | AP16: 6 | AQ16: =AO16*AP16 -> 15000
C17: 106693 | D17: GoodWe | E17: GW4200-DNS-30 | F17: Inversor On Grid Monofásico GoodWe 4.2kW – 2 MPPT | G17: 366652.63 | J17: Clams medio | K17: =$G$80 -> 496 | L17: 12 | M17: =K17*L17 -> 5952 | O17: Clams medio | P17: =$G$80 -> 496 | Q17: 12 | R17: =P17*Q17 -> 5952 | T17: Clams medio | U17: =$G$80 -> 496 | V17: 22 | W17: =U17*V17 -> 10912 | Y17: Clams medio | Z17: =$G$80 -> 496 | AA17: 22 | AB17: =Z17*AA17 -> 10912 | AD17: Clams medio | AE17: =$G$80 -> 496 | AF17: 24 | AG17: =AE17*AF17 -> 11904 | AI17: Clams medio | AJ17: =$G$80 -> 496 | AK17: 30 | AL17: =AJ17*AK17 -> 14880 | AN17: Clams medio | AO17: =$G$80 -> 496 | AP17: 30 | AQ17: =AO17*AP17 -> 14880
C18: 106692 | D18: GoodWe | E18: GW5000-DNS-30 | F18: Inversor On Grid Monofásico GoodWe 5kW – 2 MPPT | G18: 380800 | J18: Clams final | K18: =$G$79 -> 496 | L18: 4 | M18: =K18*L18 -> 1984 | O18: Clams final | P18: =$G$79 -> 496 | Q18: 4 | R18: =P18*Q18 -> 1984 | T18: Clams final | U18: =$G$79 -> 496 | V18: 4 | W18: =U18*V18 -> 1984 | Y18: Clams final | Z18: =$G$79 -> 496 | AA18: 4 | AB18: =Z18*AA18 -> 1984 | AD18: Clams final | AE18: =$G$79 -> 496 | AF18: 8 | AG18: =AE18*AF18 -> 3968 | AI18: Clams final | AJ18: =$G$79 -> 496 | AK18: 8 | AL18: =AJ18*AK18 -> 3968 | AN18: Clams final | AO18: =$G$79 -> 496 | AP18: 8 | AQ18: =AO18*AP18 -> 3968
C19: 106691 | D19: GoodWe | E19: GW6000-MS-30 | F19: Inversor On Grid Monofásico GoodWe 6kW – 3 MPPT | G19: 530526.32 | J19: MC4 macho | K19: =$G$9 -> 680 | L19: 4 | M19: =K19*L19 -> 2720 | O19: MC4 macho | P19: =$G$9 -> 680 | Q19: 4 | R19: =P19*Q19 -> 2720 | T19: MC4 macho | U19: =$G$9 -> 680 | V19: 4 | W19: =U19*V19 -> 2720 | Y19: MC4 macho | Z19: =$G$9 -> 680 | AA19: 4 | AB19: =Z19*AA19 -> 2720 | AD19: MC4 macho | AE19: =$G$9 -> 680 | AF19: 8 | AG19: =AE19*AF19 -> 5440 | AI19: MC4 macho | AJ19: =$G$9 -> 680 | AK19: 8 | AL19: =AJ19*AK19 -> 5440 | AN19: MC4 macho | AO19: =$G$9 -> 680 | AP19: 12 | AQ19: =AO19*AP19 -> 8160
C20: 106690 | D20: GoodWe | E20: GW8500-MS-30 | F20: Inversor On Grid Monofásico GoodWe 8.5kW – 3 MPPT | G20: 598500 | J20: MC4 hembra | K20: =$G$10 -> 680 | L20: 4 | M20: =K20*L20 -> 2720 | O20: MC4 hembra | P20: =$G$10 -> 680 | Q20: 4 | R20: =P20*Q20 -> 2720 | T20: MC4 hembra | U20: =$G$10 -> 680 | V20: 4 | W20: =U20*V20 -> 2720 | Y20: MC4 hembra | Z20: =$G$10 -> 680 | AA20: 4 | AB20: =Z20*AA20 -> 2720 | AD20: MC4 hembra | AE20: =$G$10 -> 680 | AF20: 8 | AG20: =AE20*AF20 -> 5440 | AI20: MC4 hembra | AJ20: =$G$10 -> 680 | AK20: 8 | AL20: =AJ20*AK20 -> 5440 | AN20: MC4 hembra | AO20: =$G$10 -> 680 | AP20: 12 | AQ20: =AO20*AP20 -> 8160
C21: 106689 | D21: GoodWe | E21: GW10K-MS-30 | F21: Inversor On Grid Monofásico GoodWe 10kW – 3 MPPT | G21: 637000 | J21: Cable solar rojo 6mm | K21: =$H$96 -> 947.85 | L21: 30 | M21: =K21*L21 -> 28435.5 | O21: Cable solar rojo 6mm | P21: =$H$96 -> 947.85 | Q21: 30 | R21: =P21*Q21 -> 28435.5 | T21: Cable solar rojo 6mm | U21: =$H$96 -> 947.85 | V21: 30 | W21: =U21*V21 -> 28435.5 | Y21: Cable solar rojo 6mm | Z21: =$H$96 -> 947.85 | AA21: 30 | AB21: =Z21*AA21 -> 28435.5 | AD21: Cable solar rojo 6mm | AE21: =$H$96 -> 947.85 | AF21: 30 | AG21: =AE21*AF21 -> 28435.5 | AI21: Cable solar rojo 6mm | AJ21: =$H$96 -> 947.85 | AK21: 30 | AL21: =AJ21*AK21 -> 28435.5 | AN21: Cable solar rojo 6mm | AO21: =$H$96 -> 947.85 | AP21: 30 | AQ21: =AO21*AP21 -> 28435.5
C22: 106688 | D22: GoodWe | E22: GW12K-SDT-30 | F22: Inversor On Grid Trifásico GoodWe 12kW – 2 MPPT | G22: 807130.43 | J22: Cable solar negro 6mm | K22: =H96 -> 947.85 | L22: 30 | M22: =K22*L22 -> 28435.5 | O22: Cable solar negro 6mm | P22: =$H$96 -> 947.85 | Q22: 30 | R22: =P22*Q22 -> 28435.5 | T22: Cable solar negro 6mm | U22: =$H$96 -> 947.85 | V22: 30 | W22: =U22*V22 -> 28435.5 | Y22: Cable solar negro 6mm | Z22: =$H$96 -> 947.85 | AA22: 30 | AB22: =Z22*AA22 -> 28435.5 | AD22: Cable solar negro 6mm | AE22: =$H$96 -> 947.85 | AF22: 30 | AG22: =AE22*AF22 -> 28435.5 | AI22: Cable solar negro 6mm | AJ22: =$H$96 -> 947.85 | AK22: 30 | AL22: =AJ22*AK22 -> 28435.5 | AN22: Cable solar negro 6mm | AO22: =$H$96 -> 947.85 | AP22: 30 | AQ22: =AO22*AP22 -> 28435.5
C23: 106687 | D23: GoodWe | E23: GW25K-SDT-C30 | F23: Inversor On Grid Trifásico GoodWe 25kW – 3 MPPT | G23: 1034600 | L23: neto | M23: =SUM(M11:M22) -> 2215552.7 | Q23: neto | R23: =SUM(R11:R22) -> 2231376.7 | V23: neto | W23: =SUM(W11:W22) -> 2682885.3 | AA23: neto | AB23: =SUM(AB11:AB22) -> 2751961.6 | AF23: neto | AG23: =SUM(AG11:AG22) -> 4011549.3 | AK23: neto | AL23: =SUM(AL11:AL22) -> 4529941.1 | AP23: neto | AQ23: =SUM(AQ11:AQ22) -> 4647787.4
C24: 106686 | D24: GoodWe | E24: GW50KS-MT | F24: Inversor On Grid Trifásico GoodWe 50kW – 5 MPPT | G24: 1590000 | L24: iva incluido | M24: =M23*1.19 -> 2636507.7 | Q24: iva incluido | R24: =R23*1.19 -> 2655338.3 | V24: iva incluido | W24: =W23*1.19 -> 3192633.5 | AA24: iva incluido | AB24: =AB23*1.19 -> 3274834.3 | AF24: iva incluido | AG24: =AG23*1.19 -> 4773743.7 | AK24: iva incluido | AL24: =AL23*1.19 -> 5390629.9 | AP24: iva incluido | AQ24: =AQ23*1.19 -> 5530867
C25: 107834 | D25: GoodWe | E25: GW50K-SDT-C30 | F25: Inversor On Grid Trifásico GoodWe 50kW – 5 MPPT | G25: 1527000 | L25: margen 25% | M25: =M23*0.25 -> 553888.18 | Q25: margen 25% | R25: =R23*0.25 -> 557844.18 | V25: margen 25% | W25: =W23*0.25 -> 670721.31 | AA25: margen 25% | AB25: =AB23*0.25 -> 687990.39 | AF25: margen 25% | AG25: =AG23*0.25 -> 1002887.3 | AK25: margen 25% | AL25: =AL23*0.25 -> 1132485.3 | AP25: margen 25% | AQ25: =AQ23*0.25 -> 1161946.8
C26: 106685 | D26: GoodWe | E26: GW100K-GT | F26: Inversor On Grid Trifásico GoodWe 100kW – 8 MPPT | G26: 3575600 | L26: Total | M26: =M24+M25 -> 3190395.9 | Q26: Total | R26: =R24+R25 -> 3213182.5 | V26: Total | W26: =W24+W25 -> 3863354.8 | AA26: Total | AB26: =AB24+AB25 -> 3962824.6 | AF26: Total | AG26: =AG24+AG25 -> 5776631 | AK26: Total | AL26: =AL24+AL25 -> 6523115.2 | AP26: Total | AQ26: =AQ24+AQ25 -> 6692813.8
C27: 107833 | D27: GoodWe | E27: GW125K-GT | F27: Inversor On Grid Trifásico GoodWe 125kW – 8 MPPT | G27: 3117977.3
C28: 106799 | D28: GoodWe | E28: GW15K-ET-20 | F28: Inversor Híbrido Trifásico GoodWe 15kW Híbrido – 3 MPPT | G28: 1390200
C29: 106684 | D29: GoodWe | E29: GW3000-ES-20 | F29: Inversor Híbrido Monofásico GoodWe 3kW Híbrido – 2 MPPT | G29: 795200
C30: 108055 | D30: GoodWe | E30: GW3600-ES-20 | F30: Inversor Híbrido Monofásico GoodWe 3,6kW Híbrido – 2 MPPT | G30: 811024
C31: 106683 | D31: GoodWe | E31: GW5000-ES-20 | F31: Inversor Híbrido Monofásico GoodWe 5kW Híbrido – 2 MPPT | G31: 897259.7
C32: 106682 | D32: GoodWe | E32: GW6000-ES-20 | F32: Inversor Híbrido Monofásico GoodWe 6kW Híbrido – 2 MPPT | G32: 966336 | I32: GOODWE Kit 3kW on grid | N32: GOODWE Kit 4.2kW on grid | S32: GOODWE Kit 5kW ON-Grid | X32: GOODWE Kit 6kW ON-Grid | AC32: GOODWE Kit 8.5kW On-Grid | AH32: GOODWE Kit 10kW On-Grid
C33: 106681 | D33: GoodWe | E33: GW8000-ES-C10 | F33: Inversor Híbrido Monofásico GoodWe 8kW Híbrido – 2 MPPT | G33: 1005813
C34: 107832 | D34: GoodWe | E34: GW10K-ES-C10 | F34: Inversor Híbrido Monofásico GoodWe 10kW Híbrido – 2 MPPT | G34: 1043625
C35: 108054 | D35: GoodWe | E35: GW12K-ES-C10 | F35: Inversor Híbrido Monofásico GoodWe 12kW Híbrido – 2 MPPT | G35: 1156031.2
C36: 107831 | D36: GoodWe | E36: GW3000-ES-20 Híbrido FLEX | F36: Inversor Híbrido Monofásico GoodWe 3kW Híbrido FLEX – 2 MPPT | G36: 602874.31 | L36: unidad | M36: total | Q36: unidad | R36: total | V36: unidad | W36: total | AA36: unidad | AB36: total | AF36: unidad | AG36: total | AK36: unidad | AL36: total
C37: 107000 | D37: GoodWe | E37: GW5000-ES-20 Híbrido FLEX | F37: Inversor Híbrido Monofásico GoodWe 5kW Híbrido FLEX – 2 MPPT | G37: 715432.08 | I37: TSM NEG21C.20 715Wp | J37: modulos 715W | K37: =$G$6 -> 105690.95 | L37: 6 | M37: =K37*L37 -> 634145.71 | N37: TSM NEG21C.20 715Wp | O37: modulos 715W | P37: =$G$6 -> 105690.95 | Q37: 6 | R37: =P37*Q37 -> 634145.71 | S37: TSM NEG21C.20 715Wp | T37: modulos 715W | U37: =$G$6 -> 105690.95 | V37: 9 | W37: =U37*V37 -> 951218.56 | X37: TSM NEG21C.20 715Wp | Y37: modulos 715W | Z37: =$G$6 -> 105690.95 | AA37: 9 | AB37: =Z37*AA37 -> 951218.56 | AC37: TSM NEG21C.20 715Wp | AD37: modulos 715W | AE37: =$G$6 -> 105690.95 | AF37: 14 | AG37: =AE37*AF37 -> 1479673.3 | AH37: TSM NEG21C.20 715Wp | AI37: modulos 715W | AJ37: =$G$6 -> 105690.95 | AK37: 18 | AL37: =AJ37*AK37 -> 1902437.1
C38: 106999 | D38: GoodWe | E38: GW6000-ES-20 Híbrido FLEX | F38: Inversor Híbrido Monofásico GoodWe 6kW Híbrido FLEX – 2 MPPT | G38: 794387.04 | J38: GW3000-DNS-30 | K38: =$G$16 -> 325389.47 | L38: 1 | M38: =K38*L38 -> 325389.47 | N38: Inversor On Grid Monofásico GoodWe 4.2kW – 2 MPPT | O38: GW4200-DNS-30 | P38: 366652.63 | Q38: 1 | R38: =P38*Q38 -> 366652.63 | T38: GW5000-DNS-30 | U38: =$G$18 -> 380800 | V38: 1 | W38: =U38*V38 -> 380800 | X38: Inversor On Grid Monofásico GoodWe 6kW – 3 MPPT | Y38: GW6000-MS-30 | Z38: 530526.32 | AA38: 1 | AB38: =Z38*AA38 -> 530526.32 | AD38: GW8500-MS-30 | AE38: =$G$20 -> 598500 | AF38: 1 | AG38: =AE38*AF38 -> 598500 | AI38: GW10K-MS-30 | AJ38: 637000 | AK38: 1 | AL38: =AJ38*AK38 -> 637000
C39: 107830 | D39: GoodWe | E39: GW10K-ET-20 Híbrido FLEX | F39: Inversor Híbrido Trifásico GoodWe 10kW Híbrido FLEX – 3 MPPT | G39: 924234.83 | J39: Riel 5m | K39: =$G$82 -> 18320 | L39: 3 | M39: =K39*L39 -> 54960 | O39: Riel 5m | P39: =$G$82 -> 18320 | Q39: 3 | R39: =P39*Q39 -> 54960 | T39: Riel 5m | U39: =$G$82 -> 18320 | V39: 5 | W39: =U39*V39 -> 91600 | Y39: Riel 5m | Z39: =$G$82 -> 18320 | AA39: 5 | AB39: =Z39*AA39 -> 91600 | AD39: Riel 5m | AE39: =$G$82 -> 18320 | AF39: 7 | AG39: =AE39*AF39 -> 128240 | AI39: Riel 5m | AJ39: =$G$82 -> 18320 | AK39: 9 | AL39: =AJ39*AK39 -> 164880
C40: 106997 | D40: GoodWe | E40: GW12K-ET-20 Híbrido FLEX | F40: Inversor Híbrido Trifásico GoodWe 12kW Híbrido FLEX – 3 MPPT | G40: 926830.42 | J40: Fijación Tipo L Madera | K40: =$G$69 -> 1100 | L40: 10 | M40: =K40*L40 -> 11000 | O40: Fijación Tipo L Madera | P40: =$G$69 -> 1100 | Q40: 10 | R40: =P40*Q40 -> 11000 | T40: Fijación Tipo L Madera | U40: =$G$69 -> 1100 | V40: 16 | W40: =U40*V40 -> 17600 | Y40: Fijación Tipo L Madera | Z40: =$G$69 -> 1100 | AA40: 16 | AB40: =Z40*AA40 -> 17600 | AD40: Fijación Tipo L Madera | AE40: =$G$69 -> 1100 | AF40: 22 | AG40: =AE40*AF40 -> 24200 | AI40: Fijación Tipo L Madera | AJ40: =$G$69 -> 1100 | AK40: 34 | AL40: =AJ40*AK40 -> 37400
...

Sheet DARTEL
A1: # | B1: Producto | C1: Descripción | D1: Fecha de entrega | E1: Catalogo | F1: Cantidad | G1: Precio Unitario
B2: 2088128161 | C2: INVERSOR HUAWEI ON GRID HIBRIDO MONOFASI | D2: Consultar | E2: SUN2000 -2KTL-L1 | F2: 1 | G2: 584397 | J2: Categoría | K2: SAP | L2: Marca | M2: Modelo | N2: Descripcion | O2: Precio (neto)
B3: 2088104161 | C3: INVERSOR HUAWEI ON GRID HIBRIDO MONOFASI | D3: Consultar | E3: SUN2000 -4KTL-L1 | F3: 1 | G3: 526000 | J3: Paneles Solares
B4: 2088142161 | C4: INVERSOR HUAWEI ON GRID HIBRIDO MONOFASI | D4: Consultar | E4: SUN2000 -6KTL-L1 | F4: 1 | G4: 822671
B5: 2088144161 | C5: INVERSOR HUAWEI ON GRID 6KW TRIFASICO SU | D5: Consultar | E5: SUN2000-6KTL-M1 | F5: 1 | G5: 1197762
B6: 2088146161 | C6: INVERSOR HUAWEI ON GRID 8KW TRIFASICO SU | D6: Consultar | E6: SUN2000-8KTL-M1 | F6: 1 | G6: 1300467
B7: 2088148161 | C7: INVERSOR HUAWEI ON GRID 10KW TRIFASICO S | D7: Consultar | E7: SUN2000-10KTL-M1 | F7: 1 | G7: 1528677
B8: 2088150161 | C8: INVERSOR HUAWEI ON GRID 17KW TRIFASICO S | D8: Consultar | E8: SUN2000-17KTL-M2 | F8: 1 | G8: 1945147
B9: 2088140161 | C9: INVERSOR HUAWEI ON GRID 36KW TRIFASICO S | D9: Consultar | E9: SUN2000-36KTL-M3 | F9: 1 | G9: 2917871
B10: 2088138161 | C10: INVERSOR HUAWEI ON GRID 40 KW TRIFASICO | D10: Consultar | E10: SUN2000-40KTL-M3 | F10: 1 | G10: 2910333 | J10: Conector MC4
B11: 2088156161 | C11: HUAWEI SMARTACU-2000D-1MBUS-1PID | D11: Consultar | E11: SMARTACU-2000D-1MBUS-1PID | F11: 1 | G11: 4085832
B12: 2088132161 | C12: HUAWEI BATERIA DE LITIO LUNA2OOO 5KWH | D12: Inmediato | E12: LUNA2000-5-E0 5KWH | F12: 1 | G12: 1656177 | J12: Inversores | K12: 2088142161 | L12: HUAWEI | M12: SUN2000-6KTL-L1 | N12: INVERSOR HUAWEI ON GRID HIBRIDO MONOFASICO | O12: 625890
B13: 2088134161 | C13: HUAWEI BACKUP BOX-B0 MONOFASICO | D13: Consultar | E13: BACKUP BOX-B0 | F13: 1 | G13: 476874
B14: 2088118161 | C14: HUAWEI SMART DONGLE WLAN FE | D14: Consultar | E14: SDongleA-05 | F14: 1 | G14: 63044
B15: 2088120161 | C15: HUAWEI SMART DONGLE 4G | D15: Consultar | E15: SDONGLEA-03-AU | F15: 1 | G15: 153941 | J15: Baterías | K15: 2088132161 | L15: HUAWEI | M15: LUNA2000-5-E0 5KW | N15: HUAWEI BATERIA DE LITIO LUNA2OOO 5KWH | O15: 3249740
B16: 2088122161 | C16: HUAWEI SMART POWER SENSOR DDSU666-H | D16: Consultar | E16: DDSU666-H | F16: 1 | G16: 56485 | K16: 2088130161 | L16: HUAWEI | M16: LUNA2000-5KWCO | N16: MODULO DE POTENCIA PAR BATERIA DE LITIO
B17: 2089261128 | C17: PANEL FOTOVOLTAICO 585W JINKO SOLAR | D17: Consultar | E17: 72HL4-BDV | F17: 1 | G17: 90000
B18: 209106128 | C18: RIEL DE ALUMINIO 3405MM UI R2 | D18: Consultar | E18: UI-R2-3405 | F18: 1 | G18: 13540 | J18: Comunicación Y Smart Controller | K18: 2088122161 | L18: HUAWEI | M18: DDSU666-H | N18: HUAWEI SMART POWER SENSOR DDSU666-H | O18: 44690
B19: 209104128 | C19: RIEL DE ALUMINIO 4200MM UI R2 | D19: Inmediato | E19: UI-R2-4200 | F19: 1 | G19: 16636 | K19: 2088134161 | L19: HUAWEI | M19: BACKUP BOX-B0 | N19: HUAWEI BACKUP BOX-B0 MONOFASICO | O19: 323960
B20: 209108128 | C20: CONECTOR RIEL UI R2 | D20: Consultar | E20: UN-RC-47 | F20: 1 | G20: 700
B21: 209136128 | C21: CONECTOR DE PUESTA A TIERRA A2 | D21: Consultar | E21: UN-GL | F21: 1 | G21: 567
B22: 9001266 | C22: CONDUIT EMT IEC 32mm 1.4mm 4322 | D22: Inmediato | E22: 9001266 | F22: 1 | G22: 4900
B23: 117524266 | C23: CAJA UNIV A-11 KO 100X100X65 (HG) | D23: Inmediato | E23: 117524266 | F23: 1 | G23: 2676
B24: 330100419 | C24: CABLE RV-K POWERFLEX 1x 4.0mm2 1KV NG | D24: Inmediato | E24: 3301004, | F24: 1 | G24: 989 | J24: Racking
B25: 15350671 | C25: CABLE SOLAR 6MM NEGRO PRYSUN 1,8KV | D25: Inmediato | E25: 20325273 | F25: 1 | G25: 1196
B26: 15150671 | C26: CABLE SOLAR 6MM ROJO PRYSUN 1,8KV | D26: Inmediato | E26: 20325272 | F26: 1 | G26: 1209
B27: 4220934 | C27: PRENSA ESTOPA PG 9 4.0 a 8.0mm GRIS FNX | D27: Inmediato | E27: 4220934 | F27: 1 | G27: 135
B28: 660034 | C28: CONECTOR FOTOVOLTAICO MC4 MACHO/HEMBRA 1 | D28: Inmediato | E28: 660034 | F28: 1 | G28: 8357
B29: 2088104161 | C29: INVERSOR HUAWEI ON GRID HIBRIDO MONOFASI | D29: Inmediato | E29: SUN2000 -4KTL-L1 | F29: 1 | G29: 526000 | J29: Cable Solar | L29: PRYSUN | N29: CABLE SOLAR 4MM ROJO
B30: 2088142161 | C30: INVERSOR HUAWEI ON GRID HIBRIDO MONOFASI | D30: Consultar | E30: SUN2000 -6KTL-L1 | F30: 1 | G30: 700000 | L30: PRYSUN | N30: CABLE SOLAR 4MM NEGRO
B31: 2088132161 | C31: HUAWEI BATERIA DE LITIO LUNA2OOO 5KWH | D31: Consultar | E31: LUNA2000-5-E0 5KWH | F31: 1 | G31: 1425000
B32: 2088130161 | C32: MODULO DE POTENCIA PARA BATERIA DE LITIO | D32: Consultar | E32: LUNA2000-5KW-CO | F32: 1 | G32: 625000
B33: 2088134161 | C33: HUAWEI BACKUP BOX-B0 MONOFASICO | D33: Consultar | E33: BACKUP BOX-B0 | F33: 1 | G33: 370000
B34: 7723259 | C34: INT AUTOMATICO 2x 32A C 10KA iC60N | D34: Inmediato | E34: A9F77232 | F34: 1 | G34: 26000
B35: 7124059 | C35: INT DIFERENCIAL 2x 40A 30mA 2P | D35: Inmediato | E35: A9R71240 | F35: 1 | G35: 32100
B36: 483204 | C36: REGLETA TIERRA DIN 8Px16mm (L) | D36: Inmediato | E36: 4832 | F36: 1 | G36: 7776
B37: 15350671 | C37: CABLE SOLAR 6MM NEGRO PRYSUN 1,8KV | D37: Inmediato | E37: 20325273 | F37: 1 | G37: 1200
B38: 15150671 | C38: CABLE SOLAR 6MM ROJO PRYSUN 1,8KV | D38: Inmediato | E38: 20325272 | F38: 1 | G38: 1200
B39: 6813534 | C39: FERRUL AIS NEGRO 6.00mm 10AWGx100u | D39: Inmediato | E39: 6813534 | F39: 1 | G39: 2087
B40: 330300619 | C40: CABLE RV-K POWERFLEX 3x 6.0mm2 1KV NG | D40: Consultar | E40: 3303006G | F40: 1 | G40: 4429
...
